Workbook

Sheet TONG HOP
A1: TỔNG HỢP SỐ CUỘN KHO HƯNG YÊN – NGÀY 08/10/2026
A3: 1. KHO THIÊN SƠN
A4: STT | B4: LOẠI | C4: SỐ CUỘN | D4: KHỐI LƯỢNG (kg)
A5: 1 | B5: Cuộn inox | C5: =SUMIF('thien son'!$C$3:$C$100,"Thép cuộn inox",'thien son'!$Y$3:$Y$100) -> 450 | D5: =SUMIF('thien son'!$C$3:$C$100,"Thép cuộn inox",'thien son'!$Z$3:$Z$100) -> 9736170
A6: 2 | B6: Cuộn đen | C6: =SUMIF('thien son'!$C$3:$C$100,"Thép cuộn đen",'thien son'!$Y$3:$Y$100) -> 235 | D6: =SUMIF('thien son'!$C$3:$C$100,"Thép cuộn đen",'thien son'!$Z$3:$Z$100) -> 3350995
B7: TỔNG CỘNG | C7: =SUM(C5:C6) -> 685 | D7: =SUM(D5:D6) -> 13087165 | E7: =IF(C7=SUM('thien son'!$Y$3:$Y$100),"Khớp sheet thien son","LỆCH – kiểm tra loại hàng") -> Khớp sheet thien son
A9: 2. SHEET 568 – THEO VỊ TRÍ
A10: STT | B10: LOẠI | C10: VỊ TRÍ 568 | D10: VỊ TRÍ CPNP | E10: TỔNG
A11: 1 | B11: Cuộn inox | C11: =SUMIFS($D$20:$D$70,$C$20:$C$70,"Thép cuộn inox",$F$20:$F$70,"568") -> 0 | D11: =SUMIFS($D$20:$D$70,$C$20:$C$70,"Thép cuộn inox",$F$20:$F$70,"CPNP") -> 968 | E11: =C11+D11 -> 968
A12: 2 | B12: Cuộn đen | C12: =SUMIFS($D$20:$D$70,$C$20:$C$70,"Thép cuộn đen",$F$20:$F$70,"568") -> 687 | D12: =SUMIFS($D$20:$D$70,$C$20:$C$70,"Thép cuộn đen",$F$20:$F$70,"CPNP") -> 50 | E12: =C12+D12 -> 737
A13: 3 | B13: Cuộn cán nóng | C13: =SUMIFS($D$20:$D$70,$C$20:$C$70,"Thép cán nóng",$F$20:$F$70,"568") -> 224 | D13: =SUMIFS($D$20:$D$70,$C$20:$C$70,"Thép cán nóng",$F$20:$F$70,"CPNP") -> 259 | E13: =C13+D13 -> 483
B14: TỔNG SỐ CUỘN | C14: =SUM(C11:C13) -> 911 | D14: =SUM(D11:D13) -> 1277 | E14: =SUM(E11:E13) -> 2188
B15: Thép tấm (tấm, không phải cuộn) | C15: =SUMIFS($D$20:$D$70,$C$20:$C$70,"Thép tấm",$F$20:$F$70,"568") -> 1080 | D15: =SUMIFS($D$20:$D$70,$C$20:$C$70,"Thép tấm",$F$20:$F$70,"CPNP") -> 1330 | E15: =C15+D15 -> 2410
B16: Khối lượng tất cả (kg) | C16: =SUMIFS($E$20:$E$70,$F$20:$F$70,"568") -> 30517237 | D16: =SUMIFS($E$20:$E$70,$F$20:$F$70,"CPNP") -> 34149570 | E16: =C16+D16 -> 64666807
A17: Ghi chú: vị trí ở cột F bảng dưới được lấy theo màu chữ cột Lô trong sheet 568 (chữ đỏ = CPNP, chữ đen = 568). Nếu sai, sửa ô vàng ở cột F – bảng trên tự cập nhật.
A18: CHI TIẾT SHEET 568 (tồn đến 08/10)
A19: STT | B19: LÔ | C19: LOẠI | D19: TỒN CUỐI | E19: KHỐI LƯỢNG (kg) | F19: VỊ TRÍ
A20: 1 | B20: ='568'!B3 -> Lô 363 | C20: =TRIM('568'!C3) -> Thép cuộn đen | D20: ='568'!E3 -> 76 | E20: ='568'!AK3 -> 3209810 | F20: 568
A21: 2 | B21: ='568'!B4 -> Lô 368 | C21: =TRIM('568'!C4) -> Thép cuộn đen | D21: ='568'!E4 -> 64 | E21: ='568'!AK4 -> 1890970 | F21: 568
A22: 3 | B22: ='568'!B5 -> Lô 370 | C22: =TRIM('568'!C5) -> Thép cuộn đen | D22: ='568'!E5 -> 100 | E22: ='568'!AK5 -> 2975720 | F22: 568
A23: 4 | B23: ='568'!B6 -> Lô 374 | C23: =TRIM('568'!C6) -> Thép tấm | D23: ='568'!E6 -> 1080 | E23: ='568'!AK6 -> 2024358 | F23: 568
A24: 5 | B24: ='568'!B7 -> Lô 381 | C24: =TRIM('568'!C7) -> Thép cuộn đen | D24: ='568'!E7 -> 35 | E24: ='568'!AK7 -> 2919555 | F24: 568
A25: 6 | B25: ='568'!B8 -> Lô 382 | C25: =TRIM('568'!C8) -> Thép cuộn inox | D25: ='568'!E8 -> 0 | E25: ='568'!AK8 -> 286905 | F25: CPNP
A26: 7 | B26: ='568'!B9 -> Lô 383 | C26: =TRIM('568'!C9) -> Thép cuộn inox | D26: ='568'!E9 -> 0 | E26: ='568'!AK9 -> 740890 | F26: CPNP
A27: 8 | B27: ='568'!B10 -> Lô 384 | C27: =TRIM('568'!C10) -> Thép cuộn inox | D27: ='568'!E10 -> 2 | E27: ='568'!AK10 -> 718760 | F27: CPNP
A28: 9 | B28: ='568'!B11 -> Lô 385 | C28: =TRIM('568'!C11) -> Thép cuộn inox | D28: ='568'!E11 -> 0 | E28: ='568'!AK11 -> 718185 | F28: CPNP
A29: 10 | B29: ='568'!B12 -> Lô 387 | C29: =TRIM('568'!C12) -> Thép cuộn inox | D29: ='568'!E12 -> 27 | E29: ='568'!AK12 -> 574360 | F29: CPNP
A30: 11 | B30: ='568'!B13 -> Lô 388 | C30: =TRIM('568'!C13) -> Thép cuộn đen | D30: ='568'!E13 -> 103 | E30: ='568'!AK13 -> 3020650 | F30: 568
A31: 12 | B31: ='568'!B14 -> Lô 389 | C31: =TRIM('568'!C14) -> Thép cuộn inox | D31: ='568'!E14 -> 36 | E31: ='568'!AK14 -> 775910 | F31: CPNP
... A42: 23 | B42: ='568'!B25 -> Lô 400 | C42: =TRIM('568'!C25) -> Thép cuộn inox | D42: ='568'!E25 -> 7 | E42: ='568'!AK25 -> 158315 | F42: CPNP
A43: 24 | B43: ='568'!B25 -> Lô 400 | C43: =TRIM('568'!C26) -> Thép cuộn đen | D43: ='568'!E26 -> 50 | E43: ='568'!AK26 -> 1479590 | F43: CPNP
A44: 25 | B44: ='568'!B27 -> Lô 401 | C44: =TRIM('568'!C27) -> Thép cuộn đen | D44: ='568'!E27 -> 100 | E44: ='568'!AK27 -> 2969210 | F44: 568
A45: 26 | B45: ='568'!B28 -> Lô 402 | C45: =TRIM('568'!C28) -> Thép cuộn inox | D45: ='568'!E28 -> 32 | E45: ='568'!AK28 -> 697545 | F45: CPNP
A46: 27 | B46: ='568'!B29 -> Lô 403 | C46: =TRIM('568'!C29) -> Thép cuộn inox | D46: ='568'!E29 -> 22 | E46: ='568'!AK29 -> 479922 | F46: CPNP
A47: 28 | B47: ='568'!B30 -> Lô 404 | C47: =TRIM('568'!C30) -> Thép cuộn inox | D47: ='568'!E30 -> 30 | E47: ='568'!AK30 -> 653305 | F47: CPNP
A48: 29 | B48: ='568'!B31 -> Lô 405 | C48: =TRIM('568'!C31) -> Thép cuộn inox | D48: ='568'!E31 -> 27 | E48: ='568'!AK31 -> 590235 | F48: CPNP
A49: 30 | B49: ='568'!B32 -> Lô 406 | C49: =TRIM('568'!C32) -> Thép cuộn inox | D49: ='568'!E32 -> 29 | E49: ='568'!AK32 -> 633810 | F49: CPNP
A50: 31 | B50: ='568'!B33 -> Lô 407 | C50: =TRIM('568'!C33) -> Thép cuộn inox | D50: ='568'!E33 -> 31 | E50: ='568'!AK33 -> 680480 | F50: CPNP
A51: 32 | B51: ='568'!B34 -> Lô 408 | C51: =TRIM('568'!C34) -> Thép cuộn inox | D51: ='568'!E34 -> 32 | E51: ='568'!AK34 -> 695910 | F51: CPNP
A52: 33 | B52: ='568'!B35 -> Lô 409 | C52: =TRIM('568'!C35) -> Thép cuộn inox | D52: ='568'!E35 -> 19 | E52: ='568'!AK35 -> 413535 | F52: CPNP
...

Sheet thien son
A1: TỔNG HỢP TỒN KHO THIÊN SƠN
A2: STT | B2: QUY CÁCH | D2: SỐ LƯỢNG 10/9 | E2: 11/09 | F2: 12/09 | G2: 13/09 | H2: 14/09 | I2: 15/09 | J2: 16/09 | K2: 17/09 | L2: 18/09 | M2: 19/09 | N2: 20/09 | O2: 21/09 | P2: 22/09 | Q2: 23/09 | R2: 24/09 | S2: 25/09 | T2: 26/09 | U2: 27/09 | V2: 28/09 | W2: 29/09 | X2: 30/09 | Y2: SỐ LƯỢNG | Z2: KHỐI LƯỢNG | AA2: GHI CHÚ
A3: 1 | B3: Lô 245 | C3: Thép cuộn đen | D3: 20 | Y3: 20 | Z3: 586620 | AA3: ok
A4: 2 | B4: Lô 257 | C4: Thép cuộn đen | D4: 50 | Y4: 50 | Z4: 506640 | AA4: ok
A5: 3 | B5: Lô 259 | C5: Thép cuộn inox | D5: 33 | Y5: 33 | Z5: 711070 | AA5: ok
A6: 4 | B6: Lô 260 | C6: Thép cuộn đen | D6: 25 | E6: -25 | Y6: 25 | Z6: 185570 | AA6: ok
A7: 5 | B7: Lô 261 | C7: Thép cuộn đen | D7: 70 | Y7: 70 | Z7: 777465 | AA7: ok
A8: 6 | B8: Lô 262 | C8: Thép cuộn inox | D8: 19 | Y8: 19 | Z8: 410425 | AA8: ok
A9: 7 | B9: Lô 263 | C9: Thép cuộn inox | D9: 23 | Y9: 23 | Z9: 494730 | AA9: ok
A10: 8 | B10: Lô 265 | C10: Thép cuộn inox | D10: 44 | Y10: 44 | Z10: 958485 | AA10: ok
A11: 9 | B11: Lô 266 | C11: Thép cuộn inox | D11: 36 | Y11: 36 | Z11: 783130 | AA11: ok
A12: 10 | B12: Lô 267 | C12: Thép cuộn inox | D12: 24 | Y12: 24 | Z12: 478755 | AA12: ok
A13: 11 | B13: Lô 268 | C13: Thép cuộn đen | D13: 70 | Y13: 70 | Z13: 1294700 | AA13: ok
A14: 12 | B14: Lô 269 | C14: Thép cuộn inox | D14: 40 | Y14: 40 | Z14: 869605 | AA14: ok
A15: 13 | B15: Lô 270 | C15: Thép cuộn inox | D15: 30 | Y15: 30 | Z15: 655620 | AA15: ok
A16: 14 | B16: Lô 271 | C16: Thép cuộn inox | D16: 40 | Y16: 40 | Z16: 870450 | AA16: ok
A17: 15 | B17: Lô 272 | C17: Thép cuộn inox | D17: 40 | Y17: 40 | Z17: 876190 | AA17: ok
A18: 16 | B18: Lô 273 | C18: Thép cuộn inox | D18: 45 | Y18: 45 | Z18: 979480 | AA18: ok
... A20: 18 | B20: Lô 275 | C20: Thép cuộn inox | D20: 26 | Y20: 26 | Z20: 564870 | AA20: ok

Sheet 568
A1: TỔNG HỢP TỒN KHO 568
A2: STT | B2: QUY CÁCH | D2: SỐ LƯỢNG 10/09 | E2: SỐ LƯỢNG | F2: 11/09 | G2: 12/09 | H2: 13/09 | I2: 14/09 | J2: 15/09 | K2: 16/09 | L2: 17/09 | M2: 18/09 | N2: 19/09 | O2: 20/09 | P2: 21/09 | Q2: 22/09 | R2: 23/09 | S2: 24/09 | T2: 25/09 | U2: 26/09 | V2: 27/09 | W2: 28/09 | X2: 29/09 | Y2: 30/09 | Z2: 01/10 | AA2: 02/10 | AB2: 03/10 | AC2: 04/10 | AD2: 05/10 | AE2: 06/10 | AF2: 07/10 | AG2: 08/10 | AH2: 09/10 | AI2: 10/10 | AJ2: 11/10 | AK2: KHỐI LƯỢNG | AL2: GHI CHÚ
A3: 1 | B3: Lô 363 | C3: Thép cuộn đen | D3: 109 | E3: =D3+SUM(F3:AG3) -> 76 | F3: -33 | AK3: 3209810 | AL3: ok
A4: 2 | B4: Lô 368 | C4: Thép cuộn đen | D4: 64 | E4: =D4+SUM(F4:AG4) -> 64 | AK4: 1890970 | AL4: ok
A5: 3 | B5: Lô 370 | C5: Thép cuộn đen | D5: 100 | E5: =D5+SUM(F5:AG5) -> 100 | AK5: 2975720 | AL5: ok
A6: 4 | B6: Lô 374 | C6: Thép tấm | D6: 1080 | E6: =D6+SUM(F6:AG6) -> 1080 | AK6: 2024358 | AL6: ok
A7: 5 | B7: Lô 381 | C7: Thép cuộn đen | D7: 100 | E7: =D7+SUM(F7:AG7) -> 35 | V7: -65 | AK7: 2919555 | AL7: ok
A8: 6 | B8: Lô 382 | C8: Thép cuộn inox | D8: 13 | E8: =D8+SUM(F8:AG8) -> 0 | AD8: -13 | AK8: 286905 | AL8: ok
A9: 7 | B9: Lô 383 | C9: Thép cuộn inox | D9: 34 | E9: =D9+SUM(F9:AG9) -> 0 | J9: -28 | K9: -6 | AK9: 740890 | AL9: ok
A10: 8 | B10: Lô 384 | C10: Thép cuộn inox | D10: 33 | E10: =D10+SUM(F10:AG10) -> 2 | K10: -31 | AK10: 718760 | AL10: ok
A11: 9 | B11: Lô 385 | C11: Thép cuộn inox | D11: 33 | E11: =D11+SUM(F11:AG11) -> 0 | AD11: -33 | AK11: 718185 | AL11: ok
A12: 10 | B12: Lô 387 | C12: Thép cuộn inox | D12: 27 | E12: =D12+SUM(F12:AG12) -> 27 | AK12: 574360 | AL12: ok
A13: 11 | B13: Lô 388 | C13: Thép cuộn đen | D13: 103 | E13: =D13+SUM(F13:AG13) -> 103 | AK13: 3020650 | AL13: ok
A14: 12 | B14: Lô 389 | C14: Thép cuộn inox | D14: 36 | E14: =D14+SUM(F14:AG14) -> 36 | AK14: 775910 | AL14: ok
A15: 13 | B15: Lô 390 | C15: Thép cuộn inox | D15: 45 | E15: =D15+SUM(F15:AG15) -> 45 | AK15: 970680 | AL15: ok
A16: 14 | B16: Lô 391 | C16: Thép cuộn inox | D16: 35 | E16: =D16+SUM(F16:AG16) -> 35 | AK16: 750910 | AL16: ok
A17: 15 | B17: Lô 392 | C17: Thép cuộn inox | D17: 40 | E17: =D17+SUM(F17:AG17) -> 40 | AK17: 875975 | AL17: ok
A18: 16 | B18: Lô 393 | C18: Thép cuộn inox | D18: 44 | E18: =D18+SUM(F18:AG18) -> 44 | AK18: 950225 | AL18: ok
A19: 17 | B19: Lô 394 | C19: Thép cuộn inox | D19: 35 | E19: =D19+SUM(F19:AG19) -> 35 | AK19: 754980 | AL19: ok
A20: 18 | B20: Lô 395 | C20: Thép cuộn inox | D20: 26 | E20: =D20+SUM(F20:AG20) -> 26 | AK20: 566520 | AL20: ok
A21: 19 | B21: Lô 396 | C21: Thép cuộn inox | D21: 24 | E21: =D21+SUM(F21:AG21) -> 24 | AK21: 527960 | AL21: ok
A22: 20 | B22: Lô 397 | C22: Thép cuộn inox | D22: 33 | E22: =D22+SUM(F22:AG22) -> 33 | AK22: 723945 | AL22: ok
A23: 21 | B23: Lô 398 | C23: Thép cuộn inox | D23: 34 | E23: =D23+SUM(F23:AG23) -> 34 | AK23: 739600 | AL23: ok
... A25: 23 | B25: Lô 400 | C25: Thép cuộn inox | D25: 7 | E25: =D25+SUM(F25:AG25) -> 7 | AK25: 158315 | AL25: ok
C26: Thép cuộn đen | D26: 50 | E26: =D26+SUM(F26:AG26) -> 50 | AK26: 1479590 | AL26: ok
A27: 24 | B27: Lô 401 | C27: Thép cuộn đen | D27: 100 | E27: =D27+SUM(F27:AG27) -> 100 | AK27: 2969210 | AL27: ok
A28: 25 | B28: Lô 402 | C28: Thép cuộn inox | D28: 32 | E28: =D28+SUM(F28:AG28) -> 32 | AK28: 697545 | AL28: ok
A29: 26 | B29: Lô 403 | C29: Thép cuộn inox | D29: 22 | E29: =D29+SUM(F29:AG29) -> 22 | AK29: 479922 | AL29: ok
A30: 27 | B30: Lô 404 | C30: Thép cuộn inox | D30: 30 | E30: =D30+SUM(F30:AG30) -> 30 | AK30: 653305 | AL30: ok
A31: 28 | B31: Lô 405 | C31: Thép cuộn inox | D31: 27 | E31: =D31+SUM(F31:AG31) -> 27 | AK31: 590235 | AL31: ok
A32: 29 | B32: Lô 406 | C32: Thép cuộn inox | D32: 29 | E32: =D32+SUM(F32:AG32) -> 29 | AK32: 633810 | AL32: ok
A33: 30 | B33: Lô 407 | C33: Thép cuộn inox | D33: 31 | E33: =D33+SUM(F33:AG33) -> 31 | AK33: 680480 | AL33: ok
A34: 31 | B34: Lô 408 | C34: Thép cuộn inox | D34: 32 | E34: =D34+SUM(F34:AG34) -> 32 | AK34: 695910 | AL34: ok
A35: 32 | B35: Lô 409 | C35: Thép cuộn inox | D35: 19 | E35: =D35+SUM(F35:AG35) -> 19 | AK35: 413535 | AL35: ok
A36: 33 | B36: Lô 410 | C36: Thép cuộn inox | D36: 31 | E36: =D36+SUM(F36:AG36) -> 31 | AK36: 674520 | AL36: ok
A37: 34 | B37: Lô 411 | C37: Thép cuộn đen | D37: 70 | E37: =D37+SUM(F37:AG37) -> 70 | AK37: 2076910 | AL37: ok
A38: 35 | B38: Lô 412 | C38: Thép cuộn đen | D38: 50 | E38: =D38+SUM(F38:AG38) -> 50 | AK38: 1481435 | AL38: ok
... A42: 39 | B42: Lô 416 | C42: Thép cuộn inox | D42: 30 | E42: =D42+SUM(F42:AG42) -> 30 | AK42: 635070 | AL42: ok
A43: 40 | B43: Lô 417 | C43: Thép cán nóng | E43: =D43+SUM(F43:AG43) -> 224 | G43: 10 | H43: =8+10 -> 18 | I43: =9+9 -> 18 | J43: =9+9 -> 18 | N43: =5+8 -> 13 | O43: 9 | P43: 10 | S43: 10 | T43: 10 | U43: =3+6 -> 9 | V43: =10+10 -> 20 | W43: =8+10+10 -> 28 | X43: =10+10 -> 20 | Y43: =10+10+11 -> 31 | AK43: =2521160+2513410 -> 5034570
A44: 41 | B44: Lô 418 | C44: Thép cuộn Inox | E44: =D44+SUM(F44:AG44) -> 33 | J44: 33 | AK44: 703640
...

Sheet cpnp
A1: TỔNG HỢP TỒN KHO CỔ PHẦN NAM PHÁT
A2: STT | B2: QUY CÁCH | D2: 46304 | E2: Tồn cuối | F2: 11/09 | G2: 12/09 | H2: 13/09 | I2: 14/09 | J2: 15/09 | K2: 16/09 | L2: 17/09 | M2: 18/09 | N2: 19/09 | O2: 20/09 | P2: 21/09 | Q2: 22/09 | R2: 23/09 | S2: 24/09 | T2: 25/09 | U2: 26/09 | V2: 27/09 | W2: 28/09 | X2: 29/09 | Y2: 30/09 | Z2: 01/10 | AA2: SỐ LƯỢNG | AB2: KHỐI LƯỢNG | AC2: GHI CHÚ
A3: 1 | B3: Lô 209 | C3: Thép cuộn inox | D3: 2 | E3: =D3+SUM(F3:Z3) -> 2 | AA3: 2 | AB3: 42635 | AC3: ok
A4: 2 | B4: Lô 217 | C4: Thép cuộn inox | D4: 20 | E4: =D4+SUM(F4:Z4) -> 0 | P4: -20 | AA4: 20 | AB4: 435010 | AC4: ok
A5: 3 | B5: Lô 218 | C5: Thép cuộn inox | D5: 29 | E5: =D5+SUM(F5:Z5) -> 29 | AA5: 29 | AB5: 630800 | AC5: ok
A6: 4 | B6: Lô 219 | C6: Thép cuộn inox | D6: 20 | E6: =D6+SUM(F6:Z6) -> 20 | AA6: 20 | AB6: 437290 | AC6: ok
A7: 5 | B7: Lô 220 | C7: Thép cuộn inox | D7: 30 | E7: =D7+SUM(F7:Z7) -> 30 | AA7: 30 | AB7: 653050 | AC7: ok
A8: 6 | B8: Lô 223 | C8: Thép cuộn inox | D8: 32 | E8: =D8+SUM(F8:Z8) -> 32 | AA8: 32 | AB8: 696255 | AC8: ok
A9: 7 | B9: Lô 224 | C9: Thép cuộn inox | D9: 34 | E9: =D9+SUM(F9:Z9) -> 34 | AA9: 34 | AB9: 745765 | AC9: ok
A10: 8 | B10: Lô 225 | C10: Thép cuộn inox | D10: 35 | E10: =D10+SUM(F10:Z10) -> 35 | AA10: 35 | AB10: 761425 | AC10: ok
A11: 9 | B11: Lô 226 | C11: Thép cuộn inox | D11: 40 | E11: =D11+SUM(F11:Z11) -> 40 | AA11: 40 | AB11: 869525 | AC11: ok
A12: 10 | B12: Lô 227 | C12: Thép cuộn inox | D12: 27 | E12: =D12+SUM(F12:Z12) -> 27 | AA12: 27 | AB12: 587580 | AC12: ok
A13: 11 | B13: Lô 228 | C13: Thép cuộn inox | D13: 23 | E13: =D13+SUM(F13:Z13) -> 23 | AA13: 23 | AB13: 500255 | AC13: ok
A14: 12 | B14: Lô 230 | C14: Thép cuộn inox | D14: 40 | E14: =D14+SUM(F14:Z14) -> 40 | AA14: 40 | AB14: 870480 | AC14: ok
A15: 13 | B15: Lô 231 | C15: Thép cuộn inox | D15: 32 | E15: =D15+SUM(F15:Z15) -> 32 | AA15: 32 | AB15: 696035 | AC15: ok
A16: 14 | B16: Lô 232 | C16: Thép cuộn inox | D16: 32 | E16: =D16+SUM(F16:Z16) -> 32 | AA16: 32 | AB16: 696295 | AC16: ok
B17: lô 233 | E17: =D17+SUM(F17:Z17) -> 24 | Z17: 24
E18: =D18+SUM(F18:Y18) -> 0
E19: =D19+SUM(F19:Y19) -> 0
E20: =D20+SUM(F20:Y20) -> 0
E21: =D21+SUM(F21:Y21) -> 0
E22: =D22+SUM(F22:Y22) -> 0
E23: =D23+SUM(F23:Y23) -> 0
E24: =D24+SUM(F24:Y24) -> 0
E25: =D25+SUM(F25:Y25) -> 0
E26: =D26+SUM(F26:Y26) -> 0
E27: =D27+SUM(F27:Y27) -> 0
E28: =D28+SUM(F28:Y28) -> 0
E29: =D29+SUM(F29:Y29) -> 0

Sheet VTB
A1: TỔNG HỢP TỒN KHO VTB
A2: STT | B2: QUY CÁCH | D2: 11/09 | E2: 12/09 | F2: 13/09 | G2: 14/09 | H2: 15/09 | I2: 16/09 | J2: 17/09 | K2: 18/09 | L2: 19/09 | M2: 20/09 | N2: 21/09 | O2: 22/09 | P2: 23/09 | Q2: 24/09 | R2: 25/09 | S2: 26/09 | T2: 27/09 | U2: 28/09 | V2: 29/09 | W2: 30/09 | X2: SỐ LƯỢNG | Y2: KHỐI LƯỢNG | Z2: GHI CHÚ
A3: 1 | B3: Lô 180 | C3: Thép cuộn inox | X3: 17 | Y3: 363550 | Z3: ok
A4: 2 | B4: Lô 184 | C4: Thép cuộn inox | X4: 10 | Y4: 215090 | Z4: ok
A5: 3 | B5: Lô 185 | C5: Thép cuộn inox | X5: 28 | Y5: 601805 | Z5: ok
A6: 4 | B6: Lô 192 | C6: Thép cuộn inox | X6: 20 | Y6: 432190 | Z6: ok
A7: 5 | B7: Lô 193 | C7: Thép cuộn inox | X7: 19 | Y7: 409060 | Z7: ok
A8: 6 | B8: Lô 196 | C8: Thép cuộn inox | X8: 18 | Y8: 387505 | Z8: ok
A9: 7 | B9: Lô 198 | C9: Thép cuộn inox | X9: 40 | Y9: 868247 | Z9: ok
A10: 8 | B10: Lô 200 | C10: Thép cuộn inox | J10: -15 | X10: 34 | Y10: 365955 | Z10: ok
A11: 9 | B11: Lô 201 | C11: Thép cuộn inox | X11: 53 | Y11: 706345 | Z11: ok
A12: 10 | B12: Lô 204 | C12: Thép cuộn inox | X12: 7 | Y12: 34155 | Z12: ok
A13: 11 | B13: Lô 208 | C13: Thép cuộn inox | X13: 40 | Y13: 870175 | Z13: ok
A14: 12 | B14: Lô 209 | C14: Thép cuộn inox | X14: 30 | Y14: 657930 | Z14: ok
A15: 13 | B15: Lô 210 | C15: Thép cuộn inox | X15: 25 | Y15: 544605 | Z15: ok
A16: 14 | B16: Lô 211 | C16: Thép cuộn inox | X16: 28 | Y16: 609095 | Z16: ok
A17: 15 | B17: Lô 212 | C17: Thép cuộn inox | X17: 25 | Y17: 543920 | Z17: ok

Sheet viet nhat
A1: TỔNG HỢP TỒN KHO VIỆT NHẬT
A2: STT | B2: QUY CÁCH | C2: SỐ LƯỢNG | D2: KHỐI LƯỢNG | E2: GHI CHÚ
A3: 1 | B3: Thép cuộn
A4: 2 | B4: Kiện kẽm | C4: 20
A9: STT | B9: QUY CÁCH | D9: SỐ LƯỢNG | E9: KHỐI LƯỢNG
A10: 1 | B10: Lô 179 | C10: Kiện kẽm | D10: 20
A12: TỔNG HỢP TỒN KHO THUẬN PHÁT
A13: STT | B13: QUY CÁCH | C13: SỐ LƯỢNG | D13: KHỐI LƯỢNG | E13: GHI CHÚ
A14: 1 | B14: Thép cuộn
A15: 2 | B15: Thép cuộn MK
A20: STT | B20: QUY CÁCH | D20: SỐ LƯỢNG | E20: KHỐI LƯỢNG
A21: 1
A22: 2

Sheet Green Air
A1: TỔNG HỢP TỒN KHO ĐIỀU HÒA GREEN AIR
A2: STT | B2: Model | D2: SỐ LƯỢNG ( bộ ) | E2: GHI CHÚ
A3: 1 | B3: SRK09CTR-S5 | D3: 130 | E3: ok
A4: 2 | B4: SRK12CT-S5 | D4: 60 | E4: ok
A5: 3 | B5: SRK10YZP-W5 | D5: 130 | E5: ok
A6: 4 | B6: CFS- 10VGXF | D6: 2406 | E6: ok
A7: 5 | B7: CFS- 13VGXF | D7: 1402 | E7: ok
A8: 6 | B8: CFS- 18VGXF | D8: 318 | E8: ok
A9: 7 | B9: CFS- 09FGYF | D9: 700 | E9: ok
A10: 8 | B10: CFS- 12FGYF | D10: 603 | E10: ok
